Workbook

Sheet BWIC Pricing Model
A1: MUNICIPAL BOND BWIC PRICING MODEL - PROFESSIONAL EDITION
A2: Model Date: 2026-01-13 | AAA MMD Benchmark | 30/360 Day Count | Semi-Annual
A4: SECTION 1: BOND IDENTIFICATION & BLOOMBERG DATA
A5: CUSIP (Enter Here) | B5: 64971WBJ5 | C5: ← PASTE CUSIP HERE
A6: Issuer / Description | C6: ← Auto from Bloomberg
A7: Security Type | B7: GO | C7: GO / Revenue / Hospital / IDB
A8: S&P Rating | B8: AA | C8: AAA to D or NR
A9: Moody's Rating | B9: Aa2 | C9: Aaa to D or NR
A10: State | B10: NY | C10: State code
A11: Coupon (%) | B11: 5 | C11: Annual coupon rate
A12: Maturity Date | B12: 49491 | C12: Final maturity
A13: First Call Date | B13: 47665 | C13: Next call date (blank if bullet)
A14: Call Price | B14: 100 | C14: Call redemption price
A15: Total Issue Size ($MM) | B15: 150 | C15: Outstanding amount
A16: Par Amount ($) | B16: 1000000 | C16: ← YOUR BID SIZE
A17: Settlement Date | B17: 46044 | C17: ← SETTLEMENT DATE
A19: SECTION 2: MARKET CURVE LEVELS
A20: AAA MMD Yield (%) | B20: 3.5 | C20: ← MATCH MATURITY ON MMD CURVE
A21: Bloomberg BVAL Yield (%) | B21: 3.85 | C21: BVAL mid-market
A22: ICE EVAL Yield (%) | B22: 3.9 | C22: ICE evaluated price
A23: Last TRACE Trade Yield (%) | B23: 3.82 | C23: Most recent trade
A24: Last Trade Date | B24: 46032 | C24: Trade timestamp
A25: Market Regime | B25: Neutral | C25: Strong / Neutral / Weak / Crisis
A27: SECTION 3: CONCESSION ENGINE (Auto-Calculated)
A28: Component | B28: Concession (bps) | C28: Logic / Notes
A29: Credit Spread | B29: =IFS(B8="AAA",0,B8="AA+",5,B8="AA",8,B8="AA-",12,B8="A+",18,B8="A",25,B8="A-",35,B8="BBB+",50,B8="BBB",75,B8="NR",40,TRUE,25) | C29: Rating-based spread vs AAA benchmark
A30: Sector Spread | B30: =IFS(B7="GO",0,B7="Essential",2,B7="Higher Ed",5,B7="Transport",8,B7="Hospital",15,B7="Healthcare",15,B7="Housing",20,B7="IDB",25,B7="Revenue",5,TRUE,10) | C30: Sector risk premium
A31: Coupon Adjustment | B31: =IF(B11>=5,5,IF(B11>=4,2,IF(B11>=3,5,12))) | C31: Premium/discount coupon adjustment
A32: Call Risk | B32: =IF(B13="",0,IF((B13-B17)/365<2,8,IF((B13-B17)/365<5,4,IF((B13-B17)/365<10,2,1)))) | C32: Call optionality premium
A33: Issue Size Liquidity | B33: =IF(B15>500,0,IF(B15>200,2,IF(B15>100,5,IF(B15>50,8,15)))) | C33: Liquidity discount for small issues
A34: Trade Size | B34: =IF(B16<100000,5,IF(B16<1000000,0,IF(B16<3000000,3,8))) | C34: Position risk for odd-lot/jumbo
A35: Market Regime | B35: =IFS(B25="Strong",-3,B25="Neutral",0,B25="Weak",8,B25="Crisis",20,TRUE,0) | C35: Market condition adjustment
A36: TOTAL CONCESSION | B36: =SUM(B29:B35) | C36: Sum of all concession factors
A38: SECTION 4: YIELD FRAMEWORK
A39: Fair Value Yield (MMD + Concession) | B39: =B20+(B36/100) | C39: AAA MMD + total spread
A40: BVAL - Cushion (2 bps) | B40: =B21-0.02 | C40: BVAL with safety margin
A41: Inside Target (BVAL - 5 bps) | B41: =B21-0.05 | C41: Aggressive target
A42: ICE Floor | B42: =B22 | C42: Liquidity floor
A43: RECOMMENDED BID YIELD (%) | B43: =MAX(B39,MIN(B40,B21)) | C43: Best of: Fair Value or BVAL-cushion
A44: Yield to Maturity | B44: =B43
...

Sheet Scenario Analysis
A1: YIELD & PRICE SENSITIVITY ANALYSIS
A3: YIELD SCENARIOS
A4: Yield Change (bps) | B4: -25 | C4: -10 | D4: 0 | E4: 10 | F4: 25 | G4: 50
A5: New Yield (%) | B5: ='BWIC Pricing Model'!B43+-25/100 | C5: ='BWIC Pricing Model'!B43+-10/100 | D5: ='BWIC Pricing Model'!B43+0/100 | E5: ='BWIC Pricing Model'!B43+10/100 | F5: ='BWIC Pricing Model'!B43+25/100 | G5: ='BWIC Pricing Model'!B43+50/100
A6: Approx Price | B6: ='BWIC Pricing Model'!B53*(1-'BWIC Pricing Model'!B60*-25/10000) | C6: ='BWIC Pricing Model'!B53*(1-'BWIC Pricing Model'!B60*-10/10000) | D6: ='BWIC Pricing Model'!B53*(1-'BWIC Pricing Model'!B60*0/10000) | E6: ='BWIC Pricing Model'!B53*(1-'BWIC Pricing Model'!B60*10/10000) | F6: ='BWIC Pricing Model'!B53*(1-'BWIC Pricing Model'!B60*25/10000) | G6: ='BWIC Pricing Model'!B53*(1-'BWIC Pricing Model'!B60*50/10000)
A7: P&L ($) | B7: ='BWIC Pricing Model'!B16*(B6-'BWIC Pricing Model'!B53)/100 | C7: ='BWIC Pricing Model'!B16*(C6-'BWIC Pricing Model'!B53)/100 | D7: ='BWIC Pricing Model'!B16*(D6-'BWIC Pricing Model'!B53)/100 | E7: ='BWIC Pricing Model'!B16*(E6-'BWIC Pricing Model'!B53)/100 | F7: ='BWIC Pricing Model'!B16*(F6-'BWIC Pricing Model'!B53)/100 | G7: ='BWIC Pricing Model'!B16*(G6-'BWIC Pricing Model'!B53)/100
A10: SPREAD SCENARIOS
A11: Spread Change (bps) | B11: -20 | C11: -10 | D11: 0 | E11: 10 | F11: 20 | G11: 30
A12: New Spread to MMD | B12: ='BWIC Pricing Model'!B36+-20 | C12: ='BWIC Pricing Model'!B36+-10 | D12: ='BWIC Pricing Model'!B36+0 | E12: ='BWIC Pricing Model'!B36+10 | F12: ='BWIC Pricing Model'!B36+20 | G12: ='BWIC Pricing Model'!B36+30
A13: Spread P&L ($) | B13: =-'BWIC Pricing Model'!B61*-20 | C13: =-'BWIC Pricing Model'!B61*-10 | D13: =-'BWIC Pricing Model'!B61*0 | E13: =-'BWIC Pricing Model'!B61*10 | F13: =-'BWIC Pricing Model'!B61*20 | G13: =-'BWIC Pricing Model'!B61*30
A16: BID COVERAGE ANALYSIS
A17: Your Bid Yield | B17: ='BWIC Pricing Model'!B43
A18: Cover Yield Assumption | B18: ='BWIC Pricing Model'!B43+0.05 | C18: Assume 5bps back
A19: Miss Amount (bps) | B19: =(B18-B17)*100
A20: Opportunity Cost ($) | B20: ='BWIC Pricing Model'!B61*B19

Sheet Assumptions
A1: CONCESSION FRAMEWORK & PRICING GUARDRAILS
A3: CREDIT QUALITY SPREADS
A4: Rating | B4: S&P | C4: Moody's | D4: Spread (bps) | E4: Rationale
A5: Prime | B5: AAA | C5: Aaa | D5: 0 | E5: Benchmark - no spread
A6: High Grade | B6: AA+ | C6: Aa1 | D6: 5 | E6: Minimal credit risk
A7: High Grade | B7: AA | C7: Aa2 | D7: 8 | E7: Standard high grade
A8: High Grade | B8: AA- | C8: Aa3 | D8: 12 | E8: Lower high grade
A9: Upper Medium | B9: A+ | C9: A1 | D9: 18 | E9: Upper single-A
A10: Upper Medium | B10: A | C10: A2 | D10: 25 | E10: Core single-A
A11: Upper Medium | B11: A- | C11: A3 | D11: 35 | E11: Lower single-A
A12: Lower Medium | B12: BBB+ | C12: Baa1 | D12: 50 | E12: Upper investment grade
A13: Lower Medium | B13: BBB | C13: Baa2 | D13: 75 | E13: Near IG threshold
A14: Not Rated | B14: NR | C14: NR | D14: 40 | E14: Liquidity discount
A17: SECTOR RISK PREMIUMS
A18: Sector | B18: Code | C18: Spread (bps) | D18: Risk Profile | E18: Examples
A19: General Obligation | B19: GO | C19: 0 | D19: Lowest | E19: Full faith & credit
A20: Essential Services | B20: Essential | C20: 2 | D20: Very Low | E20: Water, sewer, electric
A21: Higher Education | B21: Higher Ed | C21: 5 | D21: Low | E21: State universities
A22: Transportation | B22: Transport | C22: 8 | D22: Moderate | E22: Toll roads, airports
A23: Healthcare | B23: Hospital | C23: 15 | D23: Elevated | E23: Hospital systems
A24: Housing | B24: Housing | C24: 20 | D24: Higher | E24: Affordable housing
A25: Industrial Dev | B25: IDB | C25: 25 | D25: High | E25: Private activity
A26: Revenue (Other) | B26: Revenue | C26: 5 | D26: Low-Moderate | E26: Misc revenue bonds
A29: PRICING GUARDRAILS
A30: Rule | B30: Value | C30: Unit | D30: Purpose
A31: BVAL Cushion | B31: 2 | C31: bps | D31: Never bid through BVAL
A32: Max Concession Warning | B32: 150 | C32: bps | D32: Sanity check on total spread
A33: Stale Trade Threshold | B33: 30 | C33: days | D33: Question old trade data
A34: Near Call Warning | B34: 1 | C34: year | D34: Flag imminent call risk
A35: Min Call Protection | B35: 3 | C35: years | D35: Prefer longer protection
A36: Odd Lot Threshold | B36: 100000 | C36: $ | D36: Below = liquidity discount
A37: Jumbo Block Threshold | B37: 3000000 | C37: $ | D37: Above = position risk

Sheet Historical Spreads
A1: HISTORICAL SPREAD REFERENCE (bps vs AAA MMD)
A3: AA-RATED GENERAL OBLIGATIONS
A4: Period | B4: 10Y Avg | C4: Current | D4: Tight | E4: Wide | F4: Percentile
A5: 2024 YTD | B5: 12 | C5: 15 | D5: 8 | E5: 25 | F5: 65th
A6: 2023 | B6: 18 | C6: 15 | D6: 10 | E6: 35 | F6: 40th
A7: 2022 | B7: 25 | C7: 15 | D7: 12 | E7: 50 | F7: 30th
A8: 5-Year | B8: 15 | C8: 15 | D8: 5 | E8: 50 | F8: 50th
A9: 10-Year | B9: 12 | C9: 15 | D9: 3 | E9: 75 | F9: 60th
A12: A-RATED HEALTHCARE
A13: Period | B13: 10Y Avg | C13: Current | D13: Tight | E13: Wide | F13: Percentile
A14: 2024 YTD | B14: 55 | C14: 60 | D14: 40 | E14: 85 | F14: 60th
A15: 2023 | B15: 65 | C15: 60 | D15: 45 | E15: 100 | F15: 45th
A16: 2022 | B16: 80 | C16: 60 | D16: 50 | E16: 150 | F16: 35th
A17: 5-Year | B17: 60 | C17: 60 | D17: 35 | E17: 150 | F17: 50th
A18: 10-Year | B18: 50 | C18: 60 | D18: 25 | E18: 200 | F18: 55th

Sheet Quick Reference
A1: BWIC BIDDING QUICK REFERENCE
A3: BIDDING WORKFLOW
A4: 1. Enter CUSIP in B5 (yellow cell)
A5: 2. Verify Bloomberg auto-populated data (orange cells)
A6: 3. Enter AAA MMD yield matching bond's maturity
A7: 4. Enter your par amount (bid size)
A8: 5. Set settlement date
A9: 6. Select market regime (Strong/Neutral/Weak/Crisis)
A10: 7. Review concession breakdown (Section 3)
A11: 8. Check trading signals for warnings
A12: 9. Verify recommended bid yield and price
A13: 10. Submit bid at calculated dollar amount
A16: KEY FORMULAS
A17: Fair Value Yield | B17: =AAA MMD + Total Concession
A18: Total Concession | B18: =Credit + Sector + Coupon + Call + Size + Trade + Market
A19: Clean Price | B19: =PV of coupons + PV of principal
A20: Dirty Price | B20: =Clean Price + Accrued Interest
A21: Dollar Bid | B21: =Par Amount × (Dirty Price / 100)
A22: DV01 | B22: =Par × Duration × 0.0001
A23: Spread P&L | B23: =-DV01 × Spread Change (bps)
A26: COMMON PITFALLS
A27: • Never bid through BVAL without strong justification
A28: • Check call dates - near-call bonds trade differently
A29: • Watch for stale TRACE data (>30 days old)
A30: • Small issues (<$50MM) deserve extra liquidity concession
A31: • Hospital/healthcare spreads are volatile - add cushion
A32: • In weak markets, add defensive spread (8-20 bps)
A33: • Verify settlement date for accurate accrued interest
