Workbook

Sheet BWIC Pricing Model
A1: MUNICIPAL BOND BWIC PRICING MODEL - BLOOMBERG INTEGRATED
A2: Model Date: 2026-01-12 | AAA MMD Benchmark | Requires Bloomberg Terminal
A4: SECTION 1: CUSIP INPUT & BLOOMBERG DATA | F4: ENHANCED WORKFLOW
A5: CUSIP (Enter Here) ► | B5: 64971WBJ5 | C5: ← PASTE CUSIP, BLOOMBERG AUTO-POPULATES | F5: COMPREHENSIVE CONCESSION MODEL
F6: Uses AAA MMD as benchmark + auto-calculated spreads
A7: Issuer / Description | B7: =IFERROR(BDP(B5&" Corp","ISSUER_BULK"),"N/A - Check Bloomberg")
A8: Security Type / Sector | B8: =IFERROR(BDP(B5&" Corp","SECURITY_TYP"),"Unknown") | F8: Quick Start:
A9: S&P Rating | B9: =IFERROR(BDP(B5&" Corp","RTG_SP"),"NR") | F9: 1. Paste CUSIP in B5 (bright yellow)
A10: Moody's Rating | B10: =IFERROR(BDP(B5&" Corp","RTG_MOODY"),"NR") | F10: 2. Bloomberg auto-fills bond data (orange cells)
A11: State | B11: =IFERROR(BDP(B5&" Corp","CNTRY_OF_RISK"),"N/A") | F11: 3. Enter AAA MMD yield for maturity (B22)
A12: Coupon (%) | B12: =IFERROR(BDP(B5&" Corp","CPN"),"N/A") | F12: 4. Confirm Par Amount (B18)
A13: Maturity Date | B13: =IFERROR(BDP(B5&" Corp","MATURITY"),"N/A") | F13: 5. Select Market Regime (B29)
A14: First Call Date | B14: =IFERROR(BDP(B5&" Corp","NXT_CALL_DT"),"") | F14: 6. Review concession breakdown (Section 4)
A15: Call Price | B15: =IFERROR(BDP(B5&" Corp","NXT_CALL_PX"),"") | F15: 7. Check recommended bid (Section 5)
A16: Total Issue Size ($MM) | B16: =IFERROR(BDP(B5&" Corp","AMT_OUTSTANDING")/1000000,"N/A")
F17: Key Enhancements:
A18: Par Amount ($) - MANUAL | B18: 1000000 | F18: ✓ Credit spread: Primary driver (0-75+ bps)
A19: Settlement Date - MANUAL | B19: 45679 | F19: ✓ Sector spread: GO=0, Healthcare=15, IDB=25
F20: ✓ Issue size: <$50MM = +15 bps liquidity discount
A21: SECTION 2: MARKET CURVE LEVELS (AAA Benchmark) | F21: ✓ Trade size: Odd lot = +5 bps, Jumbo = +8 bps
A22: AAA MMD Yield (%) - MANUAL | B22: 0.035 | C22: ← Match maturity on AAA MMD curve | F22: ✓ Total concession sanity check (warns >150 bps)
A23: Bloomberg BVAL Yield (%) | B23: =IFERROR(BDP(B5&" Corp","BVAL_MID_YLD")/100,"N/A")
A24: ICE EVAL Yield (%) | B24: =IFERROR(BDP(B5&" Corp","ICE_MUNI_YLD")/100,"N/A") | F24: Typical Spreads vs AAA:
A25: Last TRACE Trade Yield (%) | B25: =IFERROR(BDP(B5&" Corp","YLD_YTM_LAST")/100,"") | F25: • AA+ GO, $200MM issue: ~15-20 bps
A26: Last Trade Date | B26: =IFERROR(BDP(B5&" Corp","TRADE_DT"),"") | F26: • A rated Hospital: ~45-55 bps
F27: • AA- Small IDB (<$50MM): ~50-60 bps
A28: SECTION 3: MARKET CONDITIONS
A29: Market Regime | B29: Neutral | C29: ⬅ Select: Strong / Neutral / Weak / Crisis | F29: Color Guide:
F30: 🟨 Yellow = Manual input
A31: SECTION 4: COMPREHENSIVE CONCESSION ENGINE (Auto-Calculated) | F31: 🟧 Orange = Bloomberg data
A32: Credit Spread (bps) | B32: =IF(OR(B9="AAA",B9="Aaa"),0, IF(OR(B9="AA+",B9="Aa1"),5, IF(OR(B9="AA",B9="Aa2"),8, IF(OR(B9="AA-",B9="Aa3"),12, IF(OR(B9="A+",B9="A1"),18, IF(OR(B9="A",B9="A2"),25, IF(OR(B9="A-",B9="A3"),35, IF(OR(B9="BBB+",B9="Baa1"),50, IF(OR(B9="BBB",B9="BBB-",B9="Baa2",B9="Baa3"),75, IF(B9="NR",40,50)))))))))) | C32: Primary driver - spread vs AAA | F32: ⬜ Gray = Calculated
A33: Sector Spread (bps) | B33: =IF(OR(ISNUMBER(SEARCH("GO",B8)),ISNUMBER(SEARCH("General",B8))),0, IF(OR(ISNUMBER(SEARCH("Water",B8)),ISNUMBER(SEARCH("Sewer",B8)),ISNUMBER(SEARCH("Power",B8)),ISNUMBER(SEARCH("Electric",B8))),2, IF(OR(ISNUMBER(SEARCH("Higher",B8)),ISNUMBER(SEARCH("University",B8)),ISNUMBER(SEARCH("College",B8))),5, IF(OR(ISNUMBER(SEARCH("Transport",B8)),ISNUMBER(SEARCH("Toll",B8)),ISNUMBER(SEARCH("Airport",B8))),8, IF(OR(ISNUMBER(SEARCH("Health",B8)),ISNUMBER(SEARCH("Hospital",B8))),15, IF(OR(ISNUMBER(SEARCH("Housing",B8)),ISNUMBER(SEARCH("Multifamily",B8))),20, IF(OR(ISNUMBER(SEARCH("IDB",B8)),ISNUMBER(SEARCH("Industrial",B8))),25,10))))))) | C33: Sector risk premium | F33: 🟩 Green = Final outputs
A34: Coupon Concession (bps) | B34: =IF(ISNUMBER(B12),IF(B12>=0.05,5,IF(B12>=0.04,2,IF(B12>=0.03,5,12))),0) | C34: Coupon structure adjustment
A35: Call Concession (bps) | B35: =IF(B14="",0,IF((B14-B19)/365<=2,8,IF((B14-B19)/365<=5,4,IF((B14-B19)/365<=10,2,1)))) | C35: Call risk premium
A36: Issue Size Concession (bps) | B36: =IF(ISNUMBER(B16),IF(B16>=500,0,IF(B16>=200,2,IF(B16>=100,5,IF(B16>=50,8,15)))),5) | C36: Liquidity discount for small issues
A37: Trade Size Concession (bps) | B37: =IF(B18<100000,5,IF(B18<=1000000,0,IF(B18<=3000000,3,8))) | C37: Position risk adjustment
A38: Market Regime Adj (bps) | B38: =IF(B29="Strong",-3,IF(B29="Weak",8,IF(B29="Crisis",20,0))) | C38: Market condition factor
A39: TOTAL CONCESSION (bps) | B39: =SUM(B32:B38) | C39: =IF(B39>'Assumptions & Guardrails'!$B$72,"⚠ HIGH - Verify","Total spread vs AAA")
A41: SECTION 5: BID GUARDRAIL FRAMEWORK
A42: Step 1: AAA MMD + Total Concession | B42: =B22+(B39/10000) | C42: Fair generic level for credit
...

Sheet Assumptions & Guardrails
A1: MUNICIPAL BOND BWIC MODEL - ASSUMPTIONS & GUARDRAILS
A3: COMPREHENSIVE CONCESSION FRAMEWORK (bps vs AAA MMD)
A4: NOTE: All concessions are ADDITIVE to AAA MMD base curve. Model auto-detects characteristics from Bloomberg data.
A5: Factor | B5: Condition | C5: Concession (bps) | D5: Rationale | E5: Bloomberg Field
A6: CREDIT QUALITY
A7: Credit Rating | B7: AAA / Aaa | C7: 0 | D7: Benchmark - no spread | E7: RTG_SP / RTG_MOODY
B8: AA+ / Aa1 | C8: 5 | D8: High grade spread
B9: AA / Aa2 | C9: 8 | D9: Standard AA spread
B10: AA- / Aa3 | C10: 12 | D10: Lower AA tier
B11: A+ / A1 | C11: 18 | D11: Upper single-A
B12: A / A2 | C12: 25 | D12: Core single-A
B13: A- / A3 | C13: 35 | D13: Lower single-A
B14: BBB+ / Baa1 | C14: 50 | D14: Upper BBB - credit risk
B15: BBB / Baa2 or lower | C15: 75 | D15: Below investment grade threshold
B16: Unrated | C16: 40 | D16: No rating = liquidity discount
A18: SECTOR RISK
A19: Sector | B19: General Obligation | C19: 0 | D19: Full faith & credit - tightest | E19: SECURITY_TYP
B20: Essential Service Rev | C20: 2 | D20: Water, sewer, power - strong
B21: Higher Ed | C21: 5 | D21: University revenue - stable
B22: Transportation | C22: 8 | D22: Toll roads, airports - usage risk
B23: Healthcare | C23: 15 | D23: Hospital revenue - sector stress
B24: Housing | C24: 20 | D24: Affordable housing - volatility
B25: IDB / Private Activity | C25: 25 | D25: Industrial dev - private credit
B26: Other / Unknown | C26: 10 | D26: Default for unlabeled
A28: COUPON STRUCTURE
A29: Coupon | B29: Premium (≥5%) | C29: 5 | D29: Tax inefficient, negative convexity | E29: CPN
B30: Current (4-5%) | C30: 2 | D30: Market standard
B31: Discount (3-4%) | C31: 5 | D31: Reinvestment risk
B32: Deep Discount (<3%) | C32: 12 | D32: Significant reinvestment risk
A34: CALL STRUCTURE
A35: Callability | B35: Bullet (non-callable) | C35: 0 | D35: No call risk | E35: NXT_CALL_DT
B36: Callable <2 yrs | C36: 8 | D36: Imminent call risk
B37: Callable 2-5 yrs | C37: 4 | D37: Near-term call risk
B38: Callable 5-10 yrs | C38: 2 | D38: Moderate call risk
B39: Callable >10 yrs | C39: 1 | D39: Minimal call risk
A41: ISSUE SIZE (Liquidity)
A42: Total Issue Size | B42: Mega (>$500MM) | C42: 0 | D42: Benchmark liquidity | E42: AMT_OUTSTANDING
B43: Large ($200-500MM) | C43: 2 | D43: Good liquidity
B44: Mid ($100-200MM) | C44: 5 | D44: Average liquidity
B45: Small ($50-100MM) | C45: 8 | D45: Limited liquidity
...
